<?xml version="1.0" ?>
<!-- =================================================================================== -->
<!-- |    This document was autogenerated by xacro from main.urdf.xacro                | -->
<!-- |    EDITING THIS FILE BY HAND IS NOT RECOMMENDED                                 | -->
<!-- =================================================================================== -->
<robot name="omnibase">
  <gazebo reference="front_left_wheel_link">
    <material>Gazebo/Red</material>
  </gazebo>
  <gazebo reference="front_right_wheel_link">
    <material>Gazebo/Green</material>
  </gazebo>
  <gazebo reference="back_right_wheel_link">
    <material>Gazebo/Blue</material>
  </gazebo>
  <gazebo reference="back_left_wheel_link">
    <material>Gazebo/Yellow</material>
  </gazebo>
  <gazebo>
    <plugin filename="libgazebo_ros_control.so" name="gazebo_ros_control">
      <robotNamespace>omnibase</robotNamespace>
    </plugin>
  </gazebo>
  <gazebo reference="base_scan">
    <material>Gazebo/FlatBlack</material>
    <sensor name="lds_lfcd_sensor" type="ray">
      <pose>0 0 0 0 0 0</pose>
      <visualize>false</visualize>
      <update_rate>5</update_rate>
      <ray>
        <scan>
          <horizontal>
            <samples>360</samples>
            <resolution>1</resolution>
            <min_angle>0.0</min_angle>
            <max_angle>6.28319</max_angle>
          </horizontal>
        </scan>
        <range>
          <min>0.120</min>
          <max>3.5</max>
          <resolution>0.015</resolution>
        </range>
        <noise>
          <type>gaussian</type>
          <mean>0.0</mean>
          <stddev>0.01</stddev>
        </noise>
      </ray>
      <plugin filename="libgazebo_ros_laser.so" name="gazebo_ros_lds_lfcd_controller">
        <topicName>scan</topicName>
        <frameName>base_scan</frameName>
      </plugin>
    </sensor>
  </gazebo>
  <gazebo>
    <plugin filename="libgazebo_ros_p3d.so" name="ground_truth">
      <frameName>world</frameName>
      <bodyName>base_link</bodyName>
      <topicName>odom</topicName>
      <updateRate>30.0</updateRate>
    </plugin>
  </gazebo>
  <link name="origin_link"/>
  <link name="base_link">
    <inertial>
      <mass value="2"/>
      <inertia ixx="0.0100" ixy="0" ixz="0" iyy="0.0065" iyz="0" izz="0.0163"/>
    </inertial>
    <visual>
      <geometry>
        <mesh filename="package://omnibase_description/meshes/trotbot.dae"/>
      </geometry>
    </visual>
    <collision>
      <geometry>
        <mesh filename="package://omnibase_description/meshes/trotbot.dae"/>
      </geometry>
    </collision>
  </link>
  <joint name="base_joint" type="fixed">
    <parent link="origin_link"/>
    <child link="base_link"/>
    <origin xyz="0 0 0.02"/>
  </joint>
  <link name="front_right_wheel_link">
    <inertial>
      <mass value="0.2"/>
      <origin xyz="0 0 0"/>
      <inertia ixx="0.00467" ixy="0" ixz="0" iyy="0.00411" iyz="0" izz="0.00467"/>
    </inertial>
    <visual>
      <origin rpy="0 0 0" xyz="0 0 0"/>
      <geometry>
        <cylinder length="0.03" radius="0.06"/>
      </geometry>
    </visual>
    <collision>
      <origin rpy="0 0 0" xyz="0 0 0"/>
      <geometry>
        <cylinder length="0.03" radius="0.06"/>
      </geometry>
      <surface>
        <bounce restitution_coefficient="0.0001"/>
      </surface>
    </collision>
  </link>
  <gazebo reference="front_right_wheel_link">
    <mu1 value="0.2"/>
    <mu2 value="1.5"/>
    <kp value="10000000.0"/>
    <kd value="10000.0"/>
    <fdir1 value="0 0 1"/>
    <maxContacts value="1"/>
  </gazebo>
  <joint name="front_right_wheel" type="continuous">
    <parent link="base_link"/>
    <child link="front_right_wheel_link"/>
    <origin rpy="1.570796326794896 0 -0.78539816339" xyz="0.22 0.22 0"/>
    <axis rpy="0 0 0" xyz="0 0 1"/>
  </joint>
  <transmission name="front_right_wheel_trans" type="SimpleTransmission">
    <type>transmission_interface/SimpleTransmission</type>
    <actuator name="front_right_wheel_motor">
      <mechanicalReduction>1</mechanicalReduction>
    </actuator>
    <joint name="front_right_wheel">
      <hardwareInterface>hardware_interface/VelocityJointInterface</hardwareInterface>
    </joint>
  </transmission>
  <link name="front_left_wheel_link">
    <inertial>
      <mass value="0.2"/>
      <origin xyz="0 0 0"/>
      <inertia ixx="0.00467" ixy="0" ixz="0" iyy="0.00411" iyz="0" izz="0.00467"/>
    </inertial>
    <visual>
      <origin rpy="0 0 0" xyz="0 0 0"/>
      <geometry>
        <cylinder length="0.03" radius="0.06"/>
      </geometry>
    </visual>
    <collision>
      <origin rpy="0 0 0" xyz="0 0 0"/>
      <geometry>
        <cylinder length="0.03" radius="0.06"/>
      </geometry>
      <surface>
        <bounce restitution_coefficient="0.0001"/>
      </surface>
    </collision>
  </link>
  <gazebo reference="front_left_wheel_link">
    <mu1 value="0.2"/>
    <mu2 value="1.5"/>
    <kp value="10000000.0"/>
    <kd value="10000.0"/>
    <fdir1 value="0 0 1"/>
    <maxContacts value="1"/>
  </gazebo>
  <joint name="front_left_wheel" type="continuous">
    <parent link="base_link"/>
    <child link="front_left_wheel_link"/>
    <origin rpy="1.570796326794896 0 -2.35619449019" xyz="0.22 -0.22 0"/>
    <axis rpy="0 0 0" xyz="0 0 1"/>
  </joint>
  <transmission name="front_left_wheel_trans" type="SimpleTransmission">
    <type>transmission_interface/SimpleTransmission</type>
    <actuator name="front_left_wheel_motor">
      <mechanicalReduction>1</mechanicalReduction>
    </actuator>
    <joint name="front_left_wheel">
      <hardwareInterface>hardware_interface/VelocityJointInterface</hardwareInterface>
    </joint>
  </transmission>
  <link name="back_left_wheel_link">
    <inertial>
      <mass value="0.2"/>
      <origin xyz="0 0 0"/>
      <inertia ixx="0.00467" ixy="0" ixz="0" iyy="0.00411" iyz="0" izz="0.00467"/>
    </inertial>
    <visual>
      <origin rpy="0 0 0" xyz="0 0 0"/>
      <geometry>
        <cylinder length="0.03" radius="0.06"/>
      </geometry>
    </visual>
    <collision>
      <origin rpy="0 0 0" xyz="0 0 0"/>
      <geometry>
        <cylinder length="0.03" radius="0.06"/>
      </geometry>
      <surface>
        <bounce restitution_coefficient="0.0001"/>
      </surface>
    </collision>
  </link>
  <gazebo reference="back_left_wheel_link">
    <mu1 value="0.2"/>
    <mu2 value="1.5"/>
    <kp value="10000000.0"/>
    <kd value="10000.0"/>
    <fdir1 value="0 0 1"/>
    <maxContacts value="1"/>
  </gazebo>
  <joint name="back_left_wheel" type="continuous">
    <parent link="base_link"/>
    <child link="back_left_wheel_link"/>
    <origin rpy="1.570796326794896 0 2.35619449019" xyz="-0.22 -0.22 0"/>
    <axis rpy="0 0 0" xyz="0 0 1"/>
  </joint>
  <transmission name="back_left_wheel_trans" type="SimpleTransmission">
    <type>transmission_interface/SimpleTransmission</type>
    <actuator name="back_left_wheel_motor">
      <mechanicalReduction>1</mechanicalReduction>
    </actuator>
    <joint name="back_left_wheel">
      <hardwareInterface>hardware_interface/VelocityJointInterface</hardwareInterface>
    </joint>
  </transmission>
  <link name="back_right_wheel_link">
    <inertial>
      <mass value="0.2"/>
      <origin xyz="0 0 0"/>
      <inertia ixx="0.00467" ixy="0" ixz="0" iyy="0.00411" iyz="0" izz="0.00467"/>
    </inertial>
    <visual>
      <origin rpy="0 0 0" xyz="0 0 0"/>
      <geometry>
        <cylinder length="0.03" radius="0.06"/>
      </geometry>
    </visual>
    <collision>
      <origin rpy="0 0 0" xyz="0 0 0"/>
      <geometry>
        <cylinder length="0.03" radius="0.06"/>
      </geometry>
      <surface>
        <bounce restitution_coefficient="0.0001"/>
      </surface>
    </collision>
  </link>
  <gazebo reference="back_right_wheel_link">
    <mu1 value="0.2"/>
    <mu2 value="1.5"/>
    <kp value="10000000.0"/>
    <kd value="10000.0"/>
    <fdir1 value="0 0 1"/>
    <maxContacts value="1"/>
  </gazebo>
  <joint name="back_right_wheel" type="continuous">
    <parent link="base_link"/>
    <child link="back_right_wheel_link"/>
    <origin rpy="1.570796326794896 0 0.78539816339" xyz="-0.22 0.22 0"/>
    <axis rpy="0 0 0" xyz="0 0 1"/>
  </joint>
  <transmission name="back_right_wheel_trans" type="SimpleTransmission">
    <type>transmission_interface/SimpleTransmission</type>
    <actuator name="back_right_wheel_motor">
      <mechanicalReduction>1</mechanicalReduction>
    </actuator>
    <joint name="back_right_wheel">
      <hardwareInterface>hardware_interface/VelocityJointInterface</hardwareInterface>
    </joint>
  </transmission>
  <joint name="scan_joint" type="fixed">
    <parent link="base_link"/>
    <child link="base_scan"/>
    <origin rpy="0 0 0" xyz="-0.005 0 0.235"/>
  </joint>
  <link name="base_scan">
    <visual>
      <origin rpy="0 0 0" xyz="0 0 0.0"/>
      <geometry>
        <mesh filename="package://omnibase_description/meshes/lds.stl" scale="0.00085 0.00085 0.00085"/>
      </geometry>
      <material name="dark"/>
    </visual>
    <inertial>
      <mass value="0.114"/>
      <origin xyz="0 0 0"/>
      <inertia ixx="0.001" ixy="0.0" ixz="0.0" iyy="0.001" iyz="0.0" izz="0.001"/>
    </inertial>
  </link>
  <joint name="body_joint" type="fixed">
    <parent link="base_link"/>
    <child link="body_link"/>
    <origin rpy="1.57 0 3.14" xyz="0 0 0.03"/>
  </joint>
  <link name="body_link">
    <inertial>
      <mass value="0.1"/>
      <origin xyz="0 0 0"/>
      <inertia ixx="0.000056443" ixy="0.0" ixz="0.0" iyy="0.0012923047" iyz="0.0" izz="0.000113232"/>
    </inertial>
  </link>
</robot>
